2025-09-02 22:46:58,581 INFO    MainThread:39758 [wandb_setup.py:_flush():81] Current SDK version is 0.21.3
2025-09-02 22:46:58,581 INFO    MainThread:39758 [wandb_setup.py:_flush():81] Configure stats pid to 39758
2025-09-02 22:46:58,581 INFO    MainThread:39758 [wandb_setup.py:_flush():81] Loading settings from /home/user/.config/wandb/settings
2025-09-02 22:46:58,581 INFO    MainThread:39758 [wandb_setup.py:_flush():81] Loading settings from /home/user/Desktop/VAE/wandb/settings
2025-09-02 22:46:58,581 INFO    MainThread:39758 [wandb_setup.py:_flush():81] Loading settings from environment variables
2025-09-02 22:46:58,581 INFO    MainThread:39758 [wandb_init.py:setup_run_log_directory():686] Logging user logs to /home/user/Desktop/VAE/wandb/run-20250902_224658-02wji1qu/logs/debug.log
2025-09-02 22:46:58,581 INFO    MainThread:39758 [wandb_init.py:setup_run_log_directory():687] Logging internal logs to /home/user/Desktop/VAE/wandb/run-20250902_224658-02wji1qu/logs/debug-internal.log
2025-09-02 22:46:58,581 INFO    MainThread:39758 [wandb_init.py:init():813] calling init triggers
2025-09-02 22:46:58,581 INFO    MainThread:39758 [wandb_init.py:init():818] wandb.init called with sweep_config: {}
config: {'latent_dim': 256, 'batch_size': 64, 'epochs': 25, 'learning_rate_vae': 0.0002, 'learning_rate_classifier': 0.001, 'learning_rate_inverse': 0.001, 'architecture': 'enhanced_inverse_classifier', '_wandb': {}}
2025-09-02 22:46:58,581 INFO    MainThread:39758 [wandb_init.py:init():854] starting backend
2025-09-02 22:46:58,785 INFO    MainThread:39758 [wandb_init.py:init():857] sending inform_init request
2025-09-02 22:46:58,787 INFO    MainThread:39758 [wandb_init.py:init():865] backend started and connected
2025-09-02 22:46:58,788 INFO    MainThread:39758 [wandb_init.py:init():936] updated telemetry
2025-09-02 22:46:58,791 INFO    MainThread:39758 [wandb_init.py:init():960] communicating run to backend with 90.0 second timeout
2025-09-02 22:46:59,301 INFO    MainThread:39758 [wandb_init.py:init():1011] starting run threads in backend
2025-09-02 22:46:59,355 INFO    MainThread:39758 [wandb_run.py:_console_start():2494] atexit reg
2025-09-02 22:46:59,355 INFO    MainThread:39758 [wandb_run.py:_redirect():2342] redirect: wrap_raw
2025-09-02 22:46:59,355 INFO    MainThread:39758 [wandb_run.py:_redirect():2411] Wrapping output streams.
2025-09-02 22:46:59,355 INFO    MainThread:39758 [wandb_run.py:_redirect():2434] Redirects installed.
2025-09-02 22:46:59,356 INFO    MainThread:39758 [wandb_init.py:init():1057] run started, returning control to user process
2025-09-02 22:46:59,974 INFO    MainThread:39758 [wandb_run.py:_config_callback():1380] config_cb None None {'latent_dim': 256, 'batch_size': 64, 'epochs': 25}
2025-09-03 01:24:22,683 INFO    wandb-AsyncioManager-main:39758 [service_client.py:_forward_responses():84] Reached EOF.
2025-09-03 01:24:22,683 INFO    wandb-AsyncioManager-main:39758 [mailbox.py:close():137] Closing mailbox, abandoning 1 handles.
2025-09-03 01:24:24,255 ERROR   wandb-AsyncioManager-main:39758 [asyncio_manager.py:fn_wrap_exceptions():183] Uncaught exception in run_soon callback.
Traceback (most recent call last):
  File "/home/user/miniconda3/envs/myenv/lib/python3.11/site-packages/wandb/sdk/lib/asyncio_manager.py", line 181, in fn_wrap_exceptions
    await fn()
  File "/home/user/miniconda3/envs/myenv/lib/python3.11/site-packages/wandb/sdk/lib/service/service_client.py", line 65, in _send_server_request
    await self._writer.drain()
  File "/home/user/miniconda3/envs/myenv/lib/python3.11/asyncio/streams.py", line 392, in drain
    await self._protocol._drain_helper()
  File "/home/user/miniconda3/envs/myenv/lib/python3.11/asyncio/streams.py", line 166, in _drain_helper
    raise ConnectionResetError('Connection lost')
ConnectionResetError: Connection lost
2025-09-03 01:24:24,260 ERROR   wandb-AsyncioManager-main:39758 [asyncio_manager.py:fn_wrap_exceptions():183] Uncaught exception in run_soon callback.
Traceback (most recent call last):
  File "/home/user/miniconda3/envs/myenv/lib/python3.11/site-packages/wandb/sdk/lib/asyncio_manager.py", line 181, in fn_wrap_exceptions
    await fn()
  File "/home/user/miniconda3/envs/myenv/lib/python3.11/site-packages/wandb/sdk/lib/service/service_client.py", line 65, in _send_server_request
    await self._writer.drain()
  File "/home/user/miniconda3/envs/myenv/lib/python3.11/asyncio/streams.py", line 392, in drain
    await self._protocol._drain_helper()
  File "/home/user/miniconda3/envs/myenv/lib/python3.11/asyncio/streams.py", line 166, in _drain_helper
    raise ConnectionResetError('Connection lost')
ConnectionResetError: Connection lost
2025-09-03 01:24:24,261 ERROR   wandb-AsyncioManager-main:39758 [asyncio_manager.py:fn_wrap_exceptions():183] Uncaught exception in run_soon callback.
Traceback (most recent call last):
  File "/home/user/miniconda3/envs/myenv/lib/python3.11/site-packages/wandb/sdk/lib/asyncio_manager.py", line 181, in fn_wrap_exceptions
    await fn()
  File "/home/user/miniconda3/envs/myenv/lib/python3.11/site-packages/wandb/sdk/lib/service/service_client.py", line 65, in _send_server_request
    await self._writer.drain()
  File "/home/user/miniconda3/envs/myenv/lib/python3.11/asyncio/streams.py", line 392, in drain
    await self._protocol._drain_helper()
  File "/home/user/miniconda3/envs/myenv/lib/python3.11/asyncio/streams.py", line 166, in _drain_helper
    raise ConnectionResetError('Connection lost')
ConnectionResetError: Connection lost
